Workbook

Sheet ⓪ 表说明与全链路血缘
A1: doc 19 · 各表「业务含义与全链路血缘」总览（自动生成自 outputs/fcl_table_meta.json）
A2: 表(num) | B2: 层 | C2: 业务含义/目的 | D2: 何时来查 | E2: 为什么这样处理 | F2: 数据粒度 | G2: 上游链路 | H2: 全部上游表 | I2: 下游链路 | J2: 全部下游表 | K2: 备注
A3: ② newrez.portnewrezfc | B3: L1 源（Newrez FCL 主源） | C3: Newrez 每日推送的法拍(FCL)主源表——一笔贷款一行最新快照，含 FCL 时间线里程碑(setup/referral/firstlegal/judgment/sale)、当前阶段 fcstage、4 个 Hold 槽(fchold1..4)、拍卖金额、律师等。 Newrez 法拍全流程的原始事实底座；下游所有 FCL 计算的源头。 | D3: 想看某贷款 Newrez 原始报的 FCL 里程碑/阶段/Hold 原值，或核对下游计算是否忠实于源时。 | E3: 各 Servicer 文件格式不同，先按‘一家一张原始表’落地保真，再到 L4 统一改名/UNION，便于回溯与对账。 | F3: 1 行/贷款/dataasof（每日快照）；本 dump 取 dataasof=MAX。 | G3: Servicer 文件(S3, L0) → newrez.portnewrezfc 〔load_daily_newrez_flow.py；落库 daily_task.py:923-942(MySQL)/960-983(Redshift)〕 | H3: Servicer 文件(S3, L0) | I3: portnewrezfc → tempfc.temp_basic_data_fcl(改名) → port.basic_data_loan_fcl(全 servicer UNION，FCL 事实表) → { port.basic_data_loan_foreclosure〔GEN_FCL_DETAIL basic_data_pool_config.py:253-305〕 / port.fcl_stage_info〔GEN_FCL_STAGE :1774-2440〕 / port.basic_data_loan_foreclosure_hold〔Hold 拆槽 :466-768〕 } → bpms.sync_*〔asset_managment_config.py〕 → bpms.biz_data_view_loan_details_foreclosure(视图) → BPS 法拍面板 | J3: tempfc.temp_basic_data_fcl、port.basic_data_loan_fcl、port.basic_data_loan_foreclosure、port.fcl_stage_info、port.basic_data_loan_foreclosure_hold、bpms.sync_loan_foreclosure、bpms.sync_fcl_stage_info、bpms.sync_loan_foreclosure_hold、bpms.biz_data_view_loan_details_foreclosure
A4: ③ newrez.portnewrezbk | B4: L1 源（Newrez 破产源） | C4: Newrez 破产(BK)源表，按贷款×破产申请记录，含 bkstatus/bkchapter/bkfileddate 等编码字段。 BK 事实底座；为 FCL 提供‘是否在破产保护(暂停法拍)’的判断。 | D4: 查某贷款原始破产章节/状态/申请日，或核对 BPS 破产面板。 | E4: 破产是法拍的暂停因素，需单列保真；编码值经 datadic 解码成业务文案。 | F4: 1 行/贷款/破产申请(bkfileddate)；多次申请多行。 | G4: Servicer 文件(S3, L0) → newrez.portnewrezbk | H4: Servicer 文件(S3, L0) | I4: portnewrezbk → port.basic_data_loan_foreclosure_bankruptcy〔解码 bkstatus，basic_data_pool_config.py:331-370，JOIN newrez.portnewrezdatadic〕 → bpms.sync_loan_foreclosure_bankruptcy〔asset_managment_config.py:822-843〕 → bpms.biz_data_view_loan_details_foreclosure(视图) → BPS 破产面板 | J4: port.basic_data_loan_foreclosure_bankruptcy、bpms.sync_loan_foreclosure_bankruptcy、bpms.biz_data_view_loan_details_foreclosure
A5: ④ newrez.portnewrezlm | B5: L1 源（Newrez 损失缓解 LM 源） | C5: Newrez 损失缓解(LM)源表，按贷款×LM 周期(dealstartdate)，含 lmdeal/lmprogram/lmstatus/lmdecision 等编码。 LM 事实底座；提供‘是否在协商还款方案(暂停/替代法拍)’。 | D5: 查某贷款 LM 周期/项目/决定原值，或核对 BPS LM 面板。 | E5: LM 是法拍的替代/暂停路径，需单列保真；编码经 datadic 解码。 | F5: 1 行/贷款/LM 周期(dealstartdate)；多周期多行。 | G5: Servicer 文件(S3, L0) → newrez.portnewrezlm | H5: Servicer 文件(S3, L0) | I5: portnewrezlm → port.basic_data_loan_foreclosure_loss_mitigation〔basic_data_pool_config.py:799-843，JOIN newrez.portnewrezdatadic〕 → bpms.sync_loan_foreclosure_loss_mitigation〔asset_managment_config.py:799-819〕 → bpms.biz_data_view_loan_details_foreclosure(视图) → BPS LM 面板 | J5: port.basic_data_loan_foreclosure_loss_mitigation、bpms.sync_loan_foreclosure_loss_mitigation、bpms.biz_data_view_loan_details_foreclosure
A6: ⑤ newrez.portnewrezgeneral | B6: L1 源（Newrez 通用源） | C6: Newrez 通用源表(125 列)，含 legalstatus、delinquency_status_mba(MBA 逾期分类)、nextduedate 等账户层属性。 逾期(delinquency)支线的源头；提供 delq_status 原值。 | D6: 查某贷款原始逾期分类/法律状态/下次到期日。 | E6: 逾期与 FCL 是两条支线——逾期来自 general 表经 days360 归一，FCL 来自 portnewrezfc 显式标志；二者在 L4 汇合。FCL 码绝不由 days360 推导。 | F6: 1 行/贷款/dataasof。 | G6: Servicer 文件(S3, L0) → newrez.portnewrezgeneral | H6: Servicer 文件(S3, L0) | I6: portnewrezgeneral.delinquency_status_mba → port.portdaily_v2〔portdaily_config.py〕 → port.basic_data_daily_loan_common.delq_status(逾期支线 L2，daily_data_loan_common_config.py) → port.basic_data_daily_loan_common_clean.delinq(L3，daily_data_loan_common_clean_config.py，CASE+days360) → { port.basic_data_fcl_related.delq_status / port.fcl_stage_info.group / port.portmonthbase } → BPS | J6: port.portdaily_v2、port.basic_data_daily_loan_common、port.basic_data_daily_loan_common_clean、port.basic_data_fcl_related、port.fcl_stage_info、port.portmonthbase、bpms.sync_fcl_stage_info
A7: ⑥ newrez.portnewrezprop | B7: L1 源（Newrez 房产源） | C7: Newrez 房产源表(32 列)，含 propertystate(州，定司法/非司法)、LTV、occupancy 等。 提供物业/州属性；州决定 FCL 走司法(judicial)还是非司法路径。 | D7: 查某贷款物业州/LTV/占用情况。 | E7: 司法/非司法影响 FCL 时长与阶段口径，需物业州维度（实测 state 取自 portnewrezprop.propertystate）。 | F7: 1 行/贷款/dataasof。 | G7: Servicer 文件(S3, L0) → newrez.portnewrezprop | H7: Servicer 文件(S3, L0) | I7: portnewrezprop.propertystate → port.basic_data_daily_loan_common(州维度) / port.basic_data_loan_foreclosure(summary_judicial_foreclosure 司法标志) → bpms.sync_loan_foreclosure → BPS | J7: port.basic_data_daily_loan_common、port.basic_data_loan_foreclosure、bpms.sync_loan_foreclosure
A8: ⑦ port.basic_data_loan_fcl | B8: L4 FCL 事实表（Redshift 快照中间） | C8: Redshift FCL 事实表——portnewrezfc 等经改名后 UNION 全 6 家 servicer 的统一列宽表(每贷款最新 dataasof)。 FCL 计算的统一入口；屏蔽各 servicer 列名差异。 | D8: 查‘统一列名后的 FCL 字段值’，或定位某下游字段来自哪根统一列。 | E8: 各家列名不同，先改名(tempfc.temp_basic_data_fcl)再 UNION 成一张统一事实表，下游只面对一套列名。 | F8: 1 行/贷款（每贷款最新 dataasof）。 | G8: Servicer 文件(L0) → newrez.portnewrezfc(+各家对应表) → tempfc.temp_basic_data_fcl(改名) → port.basic_data_loan_fcl〔UNION，basic_data_pool_config.py〕 | H8: Servicer 文件(L0)、newrez.portnewrezfc、(sls/carrington/mrc/fci/selene 对应源表)、tempfc.temp_basic_data_fcl | I8: basic_data_loan_fcl → { port.basic_data_loan_foreclosure〔GEN_FCL_DETAIL :253-305〕 / port.fcl_stage_info〔GEN_FCL_STAGE :1774-2440〕 / port.basic_data_loan_foreclosure_hold〔:466-768〕 / port.basic_data_loan_foreclosure_loss_mitigation〔:799-843〕 / port.basic_data_loan_foreclosure_bankruptcy〔:331-370〕 } → bpms.sync_* → 视图 → BPS | J8: port.basic_data_loan_foreclosure、port.fcl_stage_info、port.basic_data_loan_foreclosure_hold、port.basic_data_loan_foreclosure_loss_mitigation、port.basic_data_loan_foreclosure_bankruptcy、bpms.sync_loan_foreclosure、bpms.sync_fcl_stage_info、bpms.sync_loan_foreclosure_hold、bpms.sync_loan_foreclosure_loss_mitigation、bpms.sync_loan_foreclosure_bankruptcy、bpms.biz_data_view_loan_details_foreclosure
A9: ⑧ port.basic_data_loan_foreclosure | B9: L4 FCL 聚合（时间线，1 行/贷款） | C9: Redshift FCL 聚合表(1 行/贷款)——一笔贷款端到端法拍时间线：各里程碑日期、当前状态(summary_foreclosure_status)、司法标志、在法拍天数(summary_days_in_fcl)。 bpms.sync_loan_foreclosure(BPS 主表)的直接上游；法拍主视图的数据底座。 | D9: 查某贷款法拍‘何时进入各里程碑/当前状态/在法拍多少天/为何退出’。 | E9: 把事实表里散落的里程碑/状态按业务规则(GEN_FCL_DETAIL CASE)收敛成 1 行/贷款的可读时间线；退出原因直接取 servicer 的 fcremovaldesc(无解码表)。 | F9: 1 行/贷款（含在途 + 已结）。 | G9: … → port.basic_data_loan_fcl → port.basic_data_loan_foreclosure〔GEN_FCL_DETAIL basic_data_pool_config.py:253-305；状态 CASE :273；司法 :277-279；在法拍天数 :1628〕 | H9: port.basic_data_loan_fcl、tempfc.temp_basic_data_fcl、newrez.portnewrezfc、Servicer 文件(L0) | I9: basic_data_loan_foreclosure → (Redshift→MySQL 同步 df_db_util.py:665-699 sync_to_mysql / 702-726 update_to_mysql) → bpms.sync_loan_foreclosure〔GEN_FORECLOSURE asset_managment_config.py:535-608；实时天数校正 :597-598〕 → bpms.biz_data_view_loan_details_foreclosure(视图) → BPS Summary/Timeline 面板 | J9: bpms.sync_loan_foreclosure、bpms.biz_data_view_loan_details_foreclosure
A10: ⑨ port.basic_data_fcl_related | B10: L4 FCL 关联/过滤中间表 | C10: FCL 关联属性中间表(14 列)——诉讼标志、清算类型、BK 标志、违约原因、delq_status 等。 给 stage 计算与过滤提供‘关联属性/分组键’(delq_status → stage group)。 | D10: 查某贷款 stage 分组依据、关联诉讼/清算/违约属性。 | E10: stage 计算需把逾期支线的 delq_status 与 FCL 属性合并；单列一张关联表承接，避免主时间线表过宽。 | F10: 1 行/贷款（最新 dataasof）。 | G10: { port.basic_data_loan_fcl(FCL 属性) + port.basic_data_daily_loan_common_clean.delinq(逾期码) } → port.basic_data_fcl_related〔basic_data_pool_config.py〕 | H10: port.basic_data_loan_fcl、port.basic_data_daily_loan_common_clean | I10: basic_data_fcl_related.delq_status → port.fcl_stage_info.group(stage 分组) → bpms.sync_fcl_stage_info → 视图 → BPS Stage 面板 | J10: port.fcl_stage_info、bpms.sync_fcl_stage_info、bpms.biz_data_view_loan_details_foreclosure
A11: ⑩ port.fcl_stage_info | B11: L4 阶段表（Redshift） | C11: Redshift 阶段表(48 列)——把法拍拆成 6 大阶段，每阶段 5 维(开始/天数/扣除 LM-Hold 重叠等)，每贷款最新 fctrdt。 bpms.sync_fcl_stage_info(BPS 聚合 Stage/Timeline)的上游；面板‘各阶段停留天数’的底座。 | D11: 查某贷款‘在每个阶段停留多久、扣除 LM/Hold 后净时长、当前在哪个阶段组’。 | E11: 业务关心‘卡在哪一步多久’；阶段口径复杂(N:N 扣 LM/Hold 重叠)，单列一张表算清，并 JOIN portfunding 取 funding 维。 | F11: 1 行/贷款/fctrdt。 | G11: { port.basic_data_loan_fcl + port.basic_data_fcl_related(delq_status 分组) + port.portfunding(JOIN) } → port.fcl_stage_info〔GEN_FCL_STAGE basic_data_pool_config.py:1774-2440〕 | H11: port.basic_data_loan_fcl、port.basic_data_fcl_related、port.basic_data_daily_loan_common_clean、port.portfunding | I11: fcl_stage_info → bpms.sync_fcl_stage_info〔GET_FCL_STAGE_DATA asset_managment_config.py:925-929，JOIN port.portfunding〕 → 视图 → BPS Stage 面板 | J11: bpms.sync_fcl_stage_info、bpms.biz_data_view_loan_details_foreclosure
A12: ⑪ port.portfunding | B12: L4 维度（融资池） | C12: 融资池表(57 列，1 行/贷款)——funding/deal 标识(fundingid/dealid)与池属性。 作为 JOIN 维度为 FCL 输出补 funding_id/bid_id，并做入库过滤。 | D12: 查某贷款属于哪个融资池/deal，或为何被 sync 过滤进/出。 | E12: BPS 需按 funding/bid 维展示与归集；FCL 表本身不含，运行时 JOIN portfunding 补齐(dealid→bid_id, fundingid→funding_id)。 | F12: 1 行/贷款（当前态）。 | G12: 投资/融资域(非 servicer FCL 文件) → port.portfunding | H12: 投资/融资域来源（非 FCL servicer 文件） | I12: portfunding ⋈ { port.fcl_stage_info / GEN_FORECLOSURE(asset_managment_config.py:535-608) } → bpms.sync_fcl_stage_info / bpms.sync_loan_foreclosure → 视图 → BPS | J12: port.fcl_stage_info、bpms.sync_fcl_stage_info、bpms.sync_loan_foreclosure、bpms.biz_data_view_loan_details_foreclosure
A13: ⑫ port.basic_data_loan_foreclosure_hold | B13: L4 Hold 历史（Redshift 长表） | C13: Redshift Hold 历史(长表，1 行/Hold)——把源表 4 个 Hold 槽(fchold1..4)拆成长格式；Carrington 多 Hold 先排名压进 4 槽。 bpms.sync_loan_foreclosure_hold(BPS Hold 全历史)的上游；支撑‘一笔法拍多个 Hold’。 | D13: 查某贷款全部 Hold 的起止/原因/历史。 | E13: 源表把 Hold 压成 4 个宽槽，业务要全历史，需拆槽(unpivot)成 1 行/Hold；一笔 FCL 多 Hold 是常态(非数据错误)。 | F13: 1 行/贷款/Hold 段。 | G13: newrez.portnewrezfc(fchold1..4) → port.basic_data_loan_fcl → port.basic_data_loan_foreclosure_hold〔拆槽 basic_data_pool_config.py:466-768；Carrington 排名 :504-629〕 | H13: newrez.portnewrezfc、port.basic_data_loan_fcl | I13: → bpms.sync_loan_foreclosure_hold〔GEN_FORECLOSURE_HOLD asset_managment_config.py:847-894〕 → 视图 → BPS Hold 面板 | J13: bpms.sync_loan_foreclosure_hold、bpms.biz_data_view_loan_details_foreclosure
A14: ⑬ port.basic_data_loan_foreclosure_loss_mitigation | B14: L4 LM 历史（Redshift） | C14: Redshift LM 历史(1 行/LM 周期)——按 (loanid, dealstartdate)，datadic 解码 lmdeal/lmprogram/lmstatus/lmdecision。 bpms.sync_loan_foreclosure_loss_mitigation 的上游；支撑‘一笔贷款多 LM 周期’。 | D14: 查某贷款全部 LM 周期/项目/决定(已解码)。 | E14: LM 多周期是常态；编码需经 datadic 解码成业务文案(JOIN key 拼 code+'.0')。 | F14: 1 行/贷款/LM 周期。 | G14: { newrez.portnewrezlm + newrez.portnewrezdatadic } → port.basic_data_loan_fcl 体系 → port.basic_data_loan_foreclosure_loss_mitigation〔basic_data_pool_config.py:799-843〕 | H14: newrez.portnewrezlm、newrez.portnewrezdatadic、port.basic_data_loan_fcl | I14: → bpms.sync_loan_foreclosure_loss_mitigation〔asset_managment_config.py:799-819〕 → 视图 → BPS LM 面板 | J14: bpms.sync_loan_foreclosure_loss_mitigation、bpms.biz_data_view_loan_details_foreclosure
... A16: ⑮ tempfc.temp_basic_data_fcl | B16: L4 改名临时表（Redshift 运行时中间产物） | C16: Redshift 运行时改名临时表(37 列)——把各 servicer 原始列(如 fcreferraldate)改成统一列(referral_start_date)的中间产物。 port.basic_data_loan_fcl 的直接上游；承接‘改名’这一步。 | D16: 排查‘统一列名 ↔ 源列名’映射、定位改名是否正确。 | E16: UNION 前必须先统一列名；单列一张临时表做改名，逻辑清晰、便于调试；运行时产物。 | F16: 1 行/贷款/dataasof。 | G16: newrez.portnewrezfc(各家源) → tempfc.temp_basic_data_fcl〔改名 basic_data_pool_config.py ~:1538-1565〕 | H16: newrez.portnewrezfc、Servicer 文件(L0) | I16: → port.basic_data_loan_fcl(UNION) → FCL 业务族(foreclosure/stage/hold/lm/bk) → bpms.sync_* → BPS | J16: port.basic_data_loan_fcl、port.basic_data_loan_foreclosure、port.fcl_stage_info、port.basic_data_loan_foreclosure_hold、port.basic_data_loan_foreclosure_loss_mitigation、port.basic_data_loan_foreclosure_bankruptcy
A17: ⑯ port.basic_data_daily_loan_common | B17: L2 逾期支线 统一日表（Redshift） | C17: 逾期支线 L2 统一日表(78 列)——全 servicer UNION 后的标准日表，含 delq_status、fcl_flag、lm_flag 等(asofdate)。 逾期/状态归一的统一入口；L3 清洗的上游。 | D17: 查‘统一后的每日逾期/状态原值’、对账各家归一。 | E17: 各家逾期/状态字段名与取值不同，先 UNION 成统一日表；注意 fcl_flag 在此并未真正归一(Newrez/SLS 为 NULL)，真正归一在 L4 FCL 业务族。 | F17: 1 行/贷款/asofdate。 | G17: Servicer 文件(L0) → newrez.portnewrezgeneral(等各家) → port.portdaily_v2〔portdaily_config.py〕 → port.basic_data_daily_loan_common〔daily_data_loan_common_config.py〕 | H17: Servicer 文件(L0)、newrez.portnewrezgeneral、newrez.portnewrezfc、port.portdaily_v2 | I17: → port.basic_data_daily_loan_common_clean(L3) → { port.portmonthbase / port.basic_data_fcl_related.delq_status / port.fcl_stage_info.group } → BPS | J17: port.basic_data_daily_loan_common_clean、port.basic_data_fcl_related、port.fcl_stage_info、port.portmonthbase | K17: fcl_flag 在 L2 未归一（直传，Newrez/SLS NULL）；真正归一在 L4 FCL 业务族。
A18: ⑰ port.basic_data_daily_loan_common_clean | B18: L3 逾期支线 清洗日表（Redshift） | C18: 逾期支线 L3 清洗日表(103 列)——把 delq_status 经 CASE 归一成标准 delinq 码(C/D30/D60/D90/D120P/FCL/REO/P)，并用 days360(nextduedate,fctrdt) 分桶(fctrdt)。 标准逾期码的单一来源；喂 portmonthbase 与 FCL 业务族(stage 分组)。 | D18: 查‘标准化后的逾期码/天数桶口径’、核对 days360 计算。 | E18: 业务要统一的 MBA 逾期码；文本状态(Foreclosure*/REO/Paid*)直接映射，其余按 days360 天数分桶。注意：FCL 码只来自 servicer 显式法拍状态，绝不由 days360 推导。 | F18: 1 行/贷款/fctrdt。 | G18: … → port.basic_data_daily_loan_common → port.basic_data_daily_loan_common_clean〔daily_data_loan_common_clean_config.py，CASE + days360〕 | H18: port.basic_data_daily_loan_common、port.portdaily_v2、newrez.portnewrezgeneral | I18: → { port.portmonthbase / port.basic_data_fcl_related.delq_status / port.fcl_stage_info.group } → BPS。另：旁支 port.basic_data_loan_delinq_clean(含 is_ghost_payoff 等)实测存在，但其生成代码不在 PrefectFlow 仓库(grep 0 命中，开放问题)。 | J18: port.basic_data_fcl_related、port.fcl_stage_info、port.portmonthbase | K18: 旁支 port.basic_data_loan_delinq_clean 生成代码不在仓库（grep 0 命中，开放问题），未列为确定下游。
A19: ⑱ bpms.sync_loan_foreclosure | B19: L5 BPS 直接对接（主表） | C19: BPS 法拍主表(72 列，当前态)——Summary/Timeline/target 主面板的数据源。 BPS 直接对接表；法拍主面板。 | D19: 查 BPS 主面板某字段的落库值、排查面板与 Redshift 是否一致。 | E19: L4 算好后同步到 MySQL 供 BPS 读；采用覆盖更新(coverage upsert)，并对天数做 NY 当日实时校正(+DATEDIFF)。 | F19: 1 行/贷款（过滤 timeline_referred… IS NOT NULL，即已进入法拍）。 | G19: … → port.basic_data_loan_foreclosure(Redshift) → (sync_to_mysql/update_to_mysql df_db_util.py:665-726) → bpms.sync_loan_foreclosure〔GEN_FORECLOSURE asset_managment_config.py:535-608〕（JOIN port.portfunding 取 funding_id/bid_id） | H19: port.basic_data_loan_foreclosure、port.portfunding、port.basic_data_loan_fcl | I19: → bpms.biz_data_view_loan_details_foreclosure(视图) → BPS 法拍详情/主面板 | J19: bpms.biz_data_view_loan_details_foreclosure | K19: 样例 Loan5(纯 Chapter 13 BK，未进法拍)不在本表，故本 dump 命中 4/5。
A20: ⑲ bpms.sync_fcl_stage_info | B20: L5 BPS 直接对接（阶段聚合） | C20: BPS 聚合 Stage/Timeline 表(57 列)——各阶段停留天数/时间线。 BPS Stage 面板数据源。 | D20: 查 BPS 各阶段天数落库值。 | E20: 阶段口径在 Redshift 算清后同步；JOIN portfunding 带 funding 维。 | F20: 1 行/贷款/fctrdt（过滤 activefcflag=1 且 fcremovaldate IS NULL）。 | G20: port.fcl_stage_info(⋈ port.portfunding) → bpms.sync_fcl_stage_info〔GET_FCL_STAGE_DATA asset_managment_config.py:925-929〕 | H20: port.fcl_stage_info、port.portfunding | I20: → bpms.biz_data_view_loan_details_foreclosure(视图) → BPS Stage 面板 | J20: bpms.biz_data_view_loan_details_foreclosure
A21: ⑳ bpms.biz_data_view_loan_details_foreclosure | B21: L5 BPS 详情页视图 | C21: BPS 法拍详情页视图(104 列)——把主表 + stage + hold + lm + bk 用 LEFT JOIN 拼成详情页；含 actual/var 天数。 BPS 详情页的‘一站式’读取视图。 | D21: 查详情页某列从哪几张 sync 表拼来、actual vs target 差异。 | E21: 详情页要跨 5 张面板表聚合，用视图免去前端多次查询。 | F21: 1 行/贷款/fctrdt（取最新）。 | G21: { bpms.sync_loan_foreclosure + bpms.sync_fcl_stage_info + bpms.sync_loan_foreclosure_hold + bpms.sync_loan_foreclosure_loss_mitigation + bpms.sync_loan_foreclosure_bankruptcy } → 视图(LEFT JOIN，104 列) | H21: bpms.sync_loan_foreclosure、bpms.sync_fcl_stage_info、bpms.sync_loan_foreclosure_hold、bpms.sync_loan_foreclosure_loss_mitigation、bpms.sync_loan_foreclosure_bankruptcy | I21: → BPS 法拍详情页 UI（5 面板） | J21: BPS 法拍详情页 UI
A22: ㉑ bpms.sync_loan_foreclosure_hold | B22: L5 BPS 直接对接（Hold 历史） | C22: BPS Hold 全历史(每次变更一行)。 BPS Hold 面板。 | D22: 查 BPS 上某贷款全部 Hold 落库记录。 | E22: 见 ⑫；L4 拆槽后同步覆盖更新。 | F22: 1 行/Hold 段。 | G22: port.basic_data_loan_foreclosure_hold → bpms.sync_loan_foreclosure_hold〔asset_managment_config.py:847-894〕 | H22: port.basic_data_loan_foreclosure_hold | I22: → bpms.biz_data_view_loan_details_foreclosure(视图) → BPS Hold 面板 | J22: bpms.biz_data_view_loan_details_foreclosure
A23: ㉒ bpms.sync_loan_foreclosure_loss_mitigation | B23: L5 BPS 直接对接（LM 周期历史） | C23: BPS LM 周期历史(1 行/LM 周期，已解码)。 BPS LM 面板。 | D23: 查 BPS 上某贷款全部 LM 周期落库记录。 | E23: 见 ⑬；L4 解码后同步覆盖更新。 | F23: 1 行/LM 周期。 | G23: port.basic_data_loan_foreclosure_loss_mitigation → bpms.sync_loan_foreclosure_loss_mitigation〔asset_managment_config.py:799-819〕 | H23: port.basic_data_loan_foreclosure_loss_mitigation | I23: → bpms.biz_data_view_loan_details_foreclosure(视图) → BPS LM 面板 | J23: bpms.biz_data_view_loan_details_foreclosure
A24: ㉓ bpms.sync_loan_foreclosure_bankruptcy | B24: L5 BPS 直接对接（破产记录） | C24: BPS 破产记录(1 行/破产申请，已解码)。 BPS 破产面板。 | D24: 查 BPS 上某贷款全部破产记录落库值。 | E24: 见 ⑭；L4 解码后同步覆盖更新。 | F24: 1 行/破产申请。 | G24: port.basic_data_loan_foreclosure_bankruptcy → bpms.sync_loan_foreclosure_bankruptcy〔asset_managment_config.py:822-843〕 | H24: port.basic_data_loan_foreclosure_bankruptcy | I24: → bpms.biz_data_view_loan_details_foreclosure(视图) → BPS 破产面板 | J24: bpms.biz_data_view_loan_details_foreclosure
A25: ㉔ newrez.portnewrezdatadic | B25: 字典（Newrez 解码字典） | C25: Newrez FCL 解码字典(8 列)——把 LM/BK 等编码(LMDeal/LMProgram/LMStatus/LMDecision/BKStatus 等)映射成业务文案。 给 LM/BK 等表的编码解码提供查找表。 | D25: 查某编码的业务含义、核对解码是否正确。 | E25: 源表存编码省空间，展示需文案；统一一张字典 JOIN 解码(COALESCE(dict_desc, raw_code))。 | F25: 1 行/(field_name, code)。 | G25: Servicer(Newrez) 文件(L0) → newrez.portnewrezdatadic | H25: Servicer 文件(S3, L0) | I25: ⋈ basic_data_pool_config.py(LM :835-840 / BK :367) → port.basic_data_loan_foreclosure_loss_mitigation / _bankruptcy(解码列) → bpms.sync_loan_foreclosure_loss_mitigation / _bankruptcy → 视图 → BPS | J25: port.basic_data_loan_foreclosure_loss_mitigation、port.basic_data_loan_foreclosure_bankruptcy、bpms.sync_loan_foreclosure_loss_mitigation、bpms.sync_loan_foreclosure_bankruptcy

Sheet ① 表清单 索引
A1: doc 19 — 5 个样例贷款 · FCL 全链路全表全字段原始转储（prod）
A2: 文档目的 | B2: 把 5 个样例贷款在 FCL 全链路【所有表的全部字段】逐一列出（一个 sheet 一张表），完整呈现 Newrez 源 → Redshift 中间层 → BPS 的「业务 ↔ 数据」对应关系。doc 16 仅含各面板用到的部分字段，本表是其原始数据底座。
A3: 数据来源 | B3: 全部 prod（只读）：mysql_prod（bpms + newrez 源）+ redshift_prod（port 中间层）。由 scripts/fetch_fcl_sample_raw_dump_data.py 预取到 outputs/fcl_sample_raw_dump_data.json。
A4: 目标读者 | B4: 数据工程师 · 业务分析师 · 验证人员 · 接入工程师 · 未来 AI 会话
A5: 取数口径 | B5: Newrez 源 / Redshift 快照表 dataasof=MAX(每贷款)；stage/视图 fctrdt=MAX(每贷款)；sync 基础表当前态；多行表(hold/lm/bk)取全历史。日期统一 YYYY-MM-DD；空值显示 —。业务日对齐 2026-06-01。
A6: 排版 | B6: 1 行/贷款的表 → 转置（字段为行 × 5 贷款列）；多行/贷款的表 → 平铺（记录为行 × 全字段列）。
A7: 修订历史 | B7: 2026-06-06 v4：补 doc 21 §0.1 图缺的逾期支线 L2/L3 + 改名临时表共 3 张中间表（temp_basic_data_fcl / basic_data_daily_loan_common / _clean），全链路 20→23 表。2026-06-04 v3：每表加「查询 SQL」行 + 新增解码字典 sheet（portnewrezdatadic）。2026-06-04 v2：改用 prod 重取 + 新增 Redshift 中间层 8 表。2026-06-03 v1：dev · 12 sheet。
A9: 一、Newrez 源数据表（mysql_prod.newrez）
A10: Sheet | B10: 表 / 视图 | C10: 用途 | D10: 列数 | E10: 本dump行/命中
A11: ② src·portnewrezfc | B11: newrez.portnewrezfc | C11: FCL 主源表（时间线/状态/Hold槽/金额/律师） | D11: 63 | E11: 5/5 贷款
A12: ③ src·portnewrezbk | B12: newrez.portnewrezbk | C12: 破产源表 | D12: 60 | E12: 5/5 贷款
A13: ④ src·portnewrezlm | B13: newrez.portnewrezlm | C13: 损失缓解(LM)源表 | D13: 56 | E13: 5/5 贷款
A14: ⑤ src·portnewrezgeneral | B14: newrez.portnewrezgeneral | C14: 通用源表（legalstatus / delinquency_status_mba 等） | D14: 125 | E14: 5/5 贷款
A15: ⑥ src·portnewrezprop | B15: newrez.portnewrezprop | C15: 房产源表（propertystate 等） | D15: 32 | E15: 5/5 贷款
A16: 二、Redshift 中间层（redshift_prod.port）
A17: Sheet | B17: 表 / 视图 | C17: 用途 | D17: 列数 | E17: 本dump行/命中
A18: ⑦ mid·basic_data_loan_fcl | B18: port.basic_data_loan_fcl | C18: Redshift FCL 快照中间表（portnewrezfc 全量进此；每贷款取最新 dataasof） | D18: 61 | E18: 5/5 贷款
A19: ⑧ mid·basic_data_loan_foreclosure | B19: port.basic_data_loan_foreclosure | C19: Redshift FCL 聚合表（1 行/贷款，sync_loan_foreclosure 的直接上游） | D19: 62 | E19: 5/5 贷款
A20: ⑨ mid·basic_data_fcl_related | B20: port.basic_data_fcl_related | C20: FCL 关联/过滤中间表（delq_status 等；每贷款最新 dataasof） | D20: 14 | E20: 5/5 贷款
A21: ⑩ mid·fcl_stage_info(RS) | B21: port.fcl_stage_info | C21: Redshift 阶段表（sync_fcl_stage_info 上游；每贷款最新 fctrdt） | D21: 48 | E21: 5/5 贷款
A22: ⑪ mid·portfunding | B22: port.portfunding | C22: 融资池表（入库 JOIN 过滤；1 行/贷款） | D22: 57 | E22: 5/5 贷款
A23: ⑫ mid·hold | B23: port.basic_data_loan_foreclosure_hold | C23: Redshift Hold 历史（sync_loan_foreclosure_hold 上游） | D23: 17 | E23: 21 行
A24: ⑬ mid·loss_mitigation | B24: port.basic_data_loan_foreclosure_loss_mitigation | C24: Redshift LM 历史（上游） | D24: 16 | E24: 21 行
A25: ⑭ mid·bankruptcy | B25: port.basic_data_loan_foreclosure_bankruptcy | C25: Redshift 破产历史（上游） | D25: 15 | E25: 3 行
A26: ⑮ mid·temp_basic_data_fcl | B26: tempfc.temp_basic_data_fcl | C26: Redshift 改名临时表（portnewrezfc 等原始列→统一列；运行时中间产物，basic_data_loan_fcl 的上游） | D26: 37 | E26: 5/5 贷款
A27: ⑯ mid·daily_loan_common | B27: port.basic_data_daily_loan_common | C27: 逾期支线 L2 统一日表（delq_status；每贷款最新 asofdate） | D27: 78 | E27: 5/5 贷款
A28: ⑰ mid·daily_loan_common_clean | B28: port.basic_data_daily_loan_common_clean | C28: 逾期支线 L3 清洗日表（delinq / days360；每贷款最新 fctrdt） | D28: 103 | E28: 5/5 贷款
A29: 三、BPS 直接对接表（mysql_prod.bpms）
A30: Sheet | B30: 表 / 视图 | C30: 用途 | D30: 列数 | E30: 本dump行/命中
A31: ⑱ bps·sync_loan_foreclosure | B31: bpms.sync_loan_foreclosure | C31: Summary/Timeline/target 主表 | D31: 72 | E31: 4/5 贷款
A32: ⑲ bps·sync_fcl_stage_info | B32: bpms.sync_fcl_stage_info | C32: 聚合 Stage/Timeline 表 | D32: 57 | E32: 5/5 贷款
A33: ⑳ bps·view_loan_details | B33: bpms.biz_data_view_loan_details_foreclosure（视图） | C33: 详情页视图（actual/var 天数；每贷款最新 fctrdt） | D33: 104 | E33: 5/5 贷款
A34: ㉑ bps·hold | B34: bpms.sync_loan_foreclosure_hold | C34: Hold 全历史（每次变更一行） | D34: 15 | E34: 21 行
A35: ㉒ bps·loss_mitigation | B35: bpms.sync_loan_foreclosure_loss_mitigation | C35: LM 周期历史 | D35: 22 | E35: 21 行
A36: ㉓ bps·bankruptcy | B36: bpms.sync_loan_foreclosure_bankruptcy | C36: 破产记录 | D36: 22 | E36: 3 行
A37: 四、解码字典（redshift_prod.newrez.portnewrezdatadic）
A38: Sheet | B38: 表 | C38: 用途 | D38: 字段 | E38: 本5贷款用到
A39: ㉔ dict·portnewrezdatadic | B39: newrez.portnewrezdatadic | C39: FCL 解码字典（仅列 5 样例用到的码；完整见数据字典 表26） | D39: 8 | E39: 55 码
A40: 不纳入本转储的表
A41: — | B41: port.basic_data_fcl_stage | C41: 较旧的阶段中间表（实测仅到 2025-09，已被 port.fcl_stage_info 取代）
...

Sheet ② src·portnewrezfc
A1: newrez.portnewrezfc — FCL 主源表（时间线/状态/Hold槽/金额/律师）
A2: 全 63 字段 · 取数口径：dataasof=MAX(每贷款) · 命中 5/5 贷款（无行的贷款列显示 —） · prod 实测 2026-06-04 · 业务日 2026-06-01
A3: 查询 SQL（prod 只读）： -- newrez.portnewrezfc · mysql_prod(只读) · 每贷款 dataasof=MAX(最新快照) · 业务日 2026-06-01 SELECT t.* FROM newrez.portnewrezfc t JOIN (SELECT loanid, MAX(dataasof) AS _md FROM newrez.portnewrezfc WHERE loanid IN ('7727000088','7727000672','7727004200','7727000065','7727000010') GROUP BY loanid) m ON t.loanid=m.loanid AND t.dataasof=m._md;
A4: 📋 业务含义与全链路血缘 〔自动生成·勿手改本块；改 outputs/fcl_table_meta.json 后重跑〕
A5: 业务含义/目的：Newrez 每日推送的法拍(FCL)主源表——一笔贷款一行最新快照，含 FCL 时间线里程碑(setup/referral/firstlegal/judgment/sale)、当前阶段 fcstage、4 个 Hold 槽(fchold1..4)、拍卖金额、律师等。 Newrez 法拍全流程的原始事实底座；下游所有 FCL 计算的源头。
A6: 何时来查：想看某贷款 Newrez 原始报的 FCL 里程碑/阶段/Hold 原值，或核对下游计算是否忠实于源时。
A7: 为什么这样处理：各 Servicer 文件格式不同，先按‘一家一张原始表’落地保真，再到 L4 统一改名/UNION，便于回溯与对账。
A8: 数据粒度：1 行/贷款/dataasof（每日快照）；本 dump 取 dataasof=MAX。
A9: 上游链路：Servicer 文件(S3, L0) → newrez.portnewrezfc 〔load_daily_newrez_flow.py；落库 daily_task.py:923-942(MySQL)/960-983(Redshift)〕
A10: 全部上游表：Servicer 文件(S3, L0)
A11: 下游链路：portnewrezfc → tempfc.temp_basic_data_fcl(改名) → port.basic_data_loan_fcl(全 servicer UNION，FCL 事实表) → { port.basic_data_loan_foreclosure〔GEN_FCL_DETAIL basic_data_pool_config.py:253-305〕 / port.fcl_stage_info〔GEN_FCL_STAGE :1774-2440〕 / port.basic_data_loan_foreclosure_hold〔Hold 拆槽 :466-768〕 } → bpms.sync_*〔asset_managment_config.py〕 → bpms.biz_data_view_loan_details_foreclosure(视图) → BPS 法拍面板
A12: 全部下游表：tempfc.temp_basic_data_fcl、port.basic_data_loan_fcl、port.basic_data_loan_foreclosure、port.fcl_stage_info、port.basic_data_loan_foreclosure_hold、bpms.sync_loan_foreclosure、bpms.sync_fcl_stage_info、bpms.sync_loan_foreclosure_hold、bpms.biz_data_view_loan_details_foreclosure
A13: ▲ 以上为「业务含义与全链路血缘」说明块；下方为原始数据 ────
A14: 字段 | B14: 7727000088 | C14: 7727000672 | D14: 7727004200 | E14: 7727000065 | F14: 7727000010
A15: id | B15: 1750674 | C15: 1750233 | D15: 1751818 | E15: 1750695 | F15: 1750688
A16: loanid | B16: 7727000088 | C16: 7727000672 | D16: 7727004200 | E16: 7727000065 | F16: 7727000010
A17: dataasof | B17: 2026-06-04 | C17: 2026-06-04 | D17: 2026-06-04 | E17: 2026-06-04 | F17: 2026-06-04
A18: shellpointloanid | B18: 1031718838 | C18: 1032761570 | D18: 0688132141 | E18: 1031718621 | F18: 1031718692
A19: fcsetupdate | B19: 2025-05-23 | C19: 2026-03-09 | D19: 2025-06-27 | E19: 2025-02-03 | F19: —
A20: fcreferraldate | B20: 2025-05-23 | C20: 2026-03-09 | D20: 2025-06-27 | E20: 2025-02-03 | F20: —
A21: smsdaysinfc | B21: 368 | C21: 79 | D21: 294 | E21: 254 | F21: —
A22: daysinfc | B22: 368 | C22: 79 | D22: 294 | E22: 254 | F22: —
A23: demandsentdate | B23: 2025-02-18 | C23: 2025-11-17 | D23: 2025-05-20 | E23: 2024-08-12 | F23: 2026-04-10
A24: demandexpirationdate | B24: 2025-03-25 | C24: 2025-12-22 | D24: 2025-06-24 | E24: 2024-09-18 | F24: 2026-05-15
A25: fcstage | B25: Post Sale Review (SCRA and PACER Check) | C25: Pre-Sale Review 1 (SCRA and PACER Check) | D25: Pre-Sale Review 1 (SCRA and PACER Check) | E25: Post Sale Review (SCRA and PACER Check) | F25: —
... A77: srliensaledate | B77: — | C77: — | D77: — | E77: — | F77: —

Sheet ③ src·portnewrezbk
A1: newrez.portnewrezbk — 破产源表
A2: 全 60 字段 · 取数口径：dataasof=MAX(每贷款) · 命中 5/5 贷款（无行的贷款列显示 —） · prod 实测 2026-06-04 · 业务日 2026-06-01
A3: 查询 SQL（prod 只读）： -- newrez.portnewrezbk · mysql_prod(只读) · 每贷款 dataasof=MAX(最新快照) · 业务日 2026-06-01 SELECT t.* FROM newrez.portnewrezbk t JOIN (SELECT loanid, MAX(dataasof) AS _md FROM newrez.portnewrezbk WHERE loanid IN ('7727000088','7727000672','7727004200','7727000065','7727000010') GROUP BY loanid) m ON t.loanid=m.loanid AND t.dataasof=m._md;
A4: 📋 业务含义与全链路血缘 〔自动生成·勿手改本块；改 outputs/fcl_table_meta.json 后重跑〕
A5: 业务含义/目的：Newrez 破产(BK)源表，按贷款×破产申请记录，含 bkstatus/bkchapter/bkfileddate 等编码字段。 BK 事实底座；为 FCL 提供‘是否在破产保护(暂停法拍)’的判断。
A6: 何时来查：查某贷款原始破产章节/状态/申请日，或核对 BPS 破产面板。
A7: 为什么这样处理：破产是法拍的暂停因素，需单列保真；编码值经 datadic 解码成业务文案。
A8: 数据粒度：1 行/贷款/破产申请(bkfileddate)；多次申请多行。
A9: 上游链路：Servicer 文件(S3, L0) → newrez.portnewrezbk
A10: 全部上游表：Servicer 文件(S3, L0)
A11: 下游链路：portnewrezbk → port.basic_data_loan_foreclosure_bankruptcy〔解码 bkstatus，basic_data_pool_config.py:331-370，JOIN newrez.portnewrezdatadic〕 → bpms.sync_loan_foreclosure_bankruptcy〔asset_managment_config.py:822-843〕 → bpms.biz_data_view_loan_details_foreclosure(视图) → BPS 破产面板
A12: 全部下游表：port.basic_data_loan_foreclosure_bankruptcy、bpms.sync_loan_foreclosure_bankruptcy、bpms.biz_data_view_loan_details_foreclosure
A13: ▲ 以上为「业务含义与全链路血缘」说明块；下方为原始数据 ────
A14: 字段 | B14: 7727000088 | C14: 7727000672 | D14: 7727004200 | E14: 7727000065 | F14: 7727000010
A15: id | B15: 1750674 | C15: 1750233 | D15: 1751818 | E15: 1750695 | F15: 1750688
A16: loanid | B16: 7727000088 | C16: 7727000672 | D16: 7727004200 | E16: 7727000065 | F16: 7727000010
A17: dataasof | B17: 2026-06-04 | C17: 2026-06-04 | D17: 2026-06-04 | E17: 2026-06-04 | F17: 2026-06-04
A18: shellpointloanid | B18: 1031718838 | C18: 1032761570 | D18: 0688132141 | E18: 1031718621 | F18: 1031718692
A19: bkfileddate | B19: — | C19: — | D19: — | E19: 2025-04-30 | F19: 2024-02-06
A20: bkstatus | B20: — | C20: — | D20: — | E20: 2 | F20: 1
A21: bkremovalcode | B21: — | C21: — | D21: — | E21: 1 | F21: —
A22: bkremovaldate | B22: — | C22: — | D22: — | E22: 2025-07-29 | F22: —
A23: bkchapter | B23: — | C23: — | D23: — | E23: 7 | F23: 13
A24: bkcasenumber | B24: — | C24: — | D24: — | E24: 2500228 | F24: 2310152
A25: bkpostpetitionduedate | B25: — | C25: — | D25: — | E25: — | F25: 2026-06-01
... A74: bkfilingregion | B74: — | C74: — | D74: — | E74: Northern District of WV (Martinsburg) | F74: Northern District of Florida, Gainesville Division

Sheet ④ src·portnewrezlm
A1: newrez.portnewrezlm — 损失缓解(LM)源表
A2: 全 56 字段 · 取数口径：dataasof=MAX(每贷款) · 命中 5/5 贷款（无行的贷款列显示 —） · prod 实测 2026-06-04 · 业务日 2026-06-01
A3: 查询 SQL（prod 只读）： -- newrez.portnewrezlm · mysql_prod(只读) · 每贷款 dataasof=MAX(最新快照) · 业务日 2026-06-01 SELECT t.* FROM newrez.portnewrezlm t JOIN (SELECT loanid, MAX(dataasof) AS _md FROM newrez.portnewrezlm WHERE loanid IN ('7727000088','7727000672','7727004200','7727000065','7727000010') GROUP BY loanid) m ON t.loanid=m.loanid AND t.dataasof=m._md;
A4: 📋 业务含义与全链路血缘 〔自动生成·勿手改本块；改 outputs/fcl_table_meta.json 后重跑〕
A5: 业务含义/目的：Newrez 损失缓解(LM)源表，按贷款×LM 周期(dealstartdate)，含 lmdeal/lmprogram/lmstatus/lmdecision 等编码。 LM 事实底座；提供‘是否在协商还款方案(暂停/替代法拍)’。
A6: 何时来查：查某贷款 LM 周期/项目/决定原值，或核对 BPS LM 面板。
A7: 为什么这样处理：LM 是法拍的替代/暂停路径，需单列保真；编码经 datadic 解码。
A8: 数据粒度：1 行/贷款/LM 周期(dealstartdate)；多周期多行。
A9: 上游链路：Servicer 文件(S3, L0) → newrez.portnewrezlm
A10: 全部上游表：Servicer 文件(S3, L0)
A11: 下游链路：portnewrezlm → port.basic_data_loan_foreclosure_loss_mitigation〔basic_data_pool_config.py:799-843，JOIN newrez.portnewrezdatadic〕 → bpms.sync_loan_foreclosure_loss_mitigation〔asset_managment_config.py:799-819〕 → bpms.biz_data_view_loan_details_foreclosure(视图) → BPS LM 面板
A12: 全部下游表：port.basic_data_loan_foreclosure_loss_mitigation、bpms.sync_loan_foreclosure_loss_mitigation、bpms.biz_data_view_loan_details_foreclosure
A13: ▲ 以上为「业务含义与全链路血缘」说明块；下方为原始数据 ────
A14: 字段 | B14: 7727000088 | C14: 7727000672 | D14: 7727004200 | E14: 7727000065 | F14: 7727000010
A15: id | B15: 1747370 | C15: 1746929 | D15: 1748514 | E15: 1747391 | F15: 1747384
A16: loanid | B16: 7727000088 | C16: 7727000672 | D16: 7727004200 | E16: 7727000065 | F16: 7727000010
A17: dataasof | B17: 2026-06-04 | C17: 2026-06-04 | D17: 2026-06-04 | E17: 2026-06-04 | F17: 2026-06-04
A18: shellpointloanid | B18: 1031718838 | C18: 1032761570 | D18: 0688132141 | E18: 1031718621 | F18: 1031718692
A19: hardshiptype | B19: 11 | C19: 11 | D19: 20 | E19: 11 | F19: 12
A20: borrowerintention | B20: — | C20: — | D20: — | E20: — | F20: —
A21: lmdeal | B21: 7 | C21: 4 | D21: 1 | E21: 2 | F21: 1
A22: dealstartdate | B22: 2026-02-17 | C22: 2026-02-25 | D22: 2026-01-06 | E22: 2025-07-01 | F22: 2026-04-16
A23: daysindeal | B23: 66 | C23: 99 | D23: 27 | E23: 0 | F23: 12
A24: lmstatus | B24: 112 | C24: 25 | D24: 5 | E24: 166 | F24: 112
A25: statusstartdate | B25: 2026-04-22 | C25: 2026-03-24 | D25: 2026-01-14 | E25: 2024-11-26 | F25: 2026-04-23
... A70: investorloanid | B70: 7727000088 | C70: 7727000672 | D70: 7727004200 | E70: 7727000065 | F70: 7727000010

Sheet ⑤ src·portnewrezgeneral
A1: newrez.portnewrezgeneral — 通用源表（legalstatus / delinquency_status_mba 等）
A2: 全 125 字段 · 取数口径：dataasof=MAX(每贷款) · 命中 5/5 贷款（无行的贷款列显示 —） · prod 实测 2026-06-04 · 业务日 2026-06-01
A3: 查询 SQL（prod 只读）： -- newrez.portnewrezgeneral · mysql_prod(只读) · 每贷款 dataasof=MAX(最新快照) · 业务日 2026-06-01 SELECT t.* FROM newrez.portnewrezgeneral t JOIN (SELECT loanid, MAX(dataasof) AS _md FROM newrez.portnewrezgeneral WHERE loanid IN ('7727000088','7727000672','7727004200','7727000065','7727000010') GROUP BY loanid) m ON t.loanid=m.loanid AND t.dataasof=m._md;
A4: 📋 业务含义与全链路血缘 〔自动生成·勿手改本块；改 outputs/fcl_table_meta.json 后重跑〕
A5: 业务含义/目的：Newrez 通用源表(125 列)，含 legalstatus、delinquency_status_mba(MBA 逾期分类)、nextduedate 等账户层属性。 逾期(delinquency)支线的源头；提供 delq_status 原值。
A6: 何时来查：查某贷款原始逾期分类/法律状态/下次到期日。
A7: 为什么这样处理：逾期与 FCL 是两条支线——逾期来自 general 表经 days360 归一，FCL 来自 portnewrezfc 显式标志；二者在 L4 汇合。FCL 码绝不由 days360 推导。
A8: 数据粒度：1 行/贷款/dataasof。
A9: 上游链路：Servicer 文件(S3, L0) → newrez.portnewrezgeneral
A10: 全部上游表：Servicer 文件(S3, L0)
A11: 下游链路：portnewrezgeneral.delinquency_status_mba → port.portdaily_v2〔portdaily_config.py〕 → port.basic_data_daily_loan_common.delq_status(逾期支线 L2，daily_data_loan_common_config.py) → port.basic_data_daily_loan_common_clean.delinq(L3，daily_data_loan_common_clean_config.py，CASE+days360) → { port.basic_data_fcl_related.delq_status / port.fcl_stage_info.group / port.portmonthbase } → BPS
A12: 全部下游表：port.portdaily_v2、port.basic_data_daily_loan_common、port.basic_data_daily_loan_common_clean、port.basic_data_fcl_related、port.fcl_stage_info、port.portmonthbase、bpms.sync_fcl_stage_info
A13: ▲ 以上为「业务含义与全链路血缘」说明块；下方为原始数据 ────
A14: 字段 | B14: 7727000088 | C14: 7727000672 | D14: 7727004200 | E14: 7727000065 | F14: 7727000010
A15: id | B15: 1749124 | C15: 1748683 | D15: 1750268 | E15: 1749145 | F15: 1749138
A16: loanid | B16: 7727000088 | C16: 7727000672 | D16: 7727004200 | E16: 7727000065 | F16: 7727000010
A17: dataasof | B17: 2026-06-04 | C17: 2026-06-04 | D17: 2026-06-04 | E17: 2026-06-04 | F17: 2026-06-04
A18: shellpointloanid | B18: 1031718838 | C18: 1032761570 | D18: 0688132141 | E18: 1031718621 | F18: 1031718692
A19: investorid | B19: BI2726 | C19: BI2725 | D19: BIRTT1 | E19: TT1REO | F19: BI2726
A20: investorloanid | B20: 7727000088 | C20: 7727000672 | D20: 7727004200 | E20: 7727000065 | F20: 7727000010
A21: priorservicerloannumber | B21: 9010021155 | C21: 32288235 | D21: 3260057082 | E21: 9014327961 | F21: 9014059868
A22: boarddate | B22: 2024-07-04 | C22: 2024-07-04 | D22: 2024-02-07 | E22: 2024-07-04 | F22: 2024-07-04
A23: acquisitiondate | B23: 2024-07-02 | C23: 2024-07-02 | D23: 2024-02-01 | E23: 2024-07-02 | F23: 2024-07-02
A24: acquisitionbalance | B24: 318856.09 | C24: 421270.39 | D24: 455612.06 | E24: 470399.51 | F24: 271997.47
A25: mbadelinquency | B25: 14 | C25: 6 | D25: 15 | E25: 14 | F25: 9
... A139: successorservicer | B139: — | C139: — | D139: — | E139: — | F139: —

Sheet ⑥ src·portnewrezprop
A1: newrez.portnewrezprop — 房产源表（propertystate 等）
A2: 全 32 字段 · 取数口径：dataasof=MAX(每贷款) · 命中 5/5 贷款（无行的贷款列显示 —） · prod 实测 2026-06-04 · 业务日 2026-06-01
A3: 查询 SQL（prod 只读）： -- newrez.portnewrezprop · mysql_prod(只读) · 每贷款 dataasof=MAX(最新快照) · 业务日 2026-06-01 SELECT t.* FROM newrez.portnewrezprop t JOIN (SELECT loanid, MAX(dataasof) AS _md FROM newrez.portnewrezprop WHERE loanid IN ('7727000088','7727000672','7727004200','7727000065','7727000010') GROUP BY loanid) m ON t.loanid=m.loanid AND t.dataasof=m._md;
A4: 📋 业务含义与全链路血缘 〔自动生成·勿手改本块；改 outputs/fcl_table_meta.json 后重跑〕
A5: 业务含义/目的：Newrez 房产源表(32 列)，含 propertystate(州，定司法/非司法)、LTV、occupancy 等。 提供物业/州属性；州决定 FCL 走司法(judicial)还是非司法路径。
A6: 何时来查：查某贷款物业州/LTV/占用情况。
A7: 为什么这样处理：司法/非司法影响 FCL 时长与阶段口径，需物业州维度（实测 state 取自 portnewrezprop.propertystate）。
A8: 数据粒度：1 行/贷款/dataasof。
A9: 上游链路：Servicer 文件(S3, L0) → newrez.portnewrezprop
A10: 全部上游表：Servicer 文件(S3, L0)
A11: 下游链路：portnewrezprop.propertystate → port.basic_data_daily_loan_common(州维度) / port.basic_data_loan_foreclosure(summary_judicial_foreclosure 司法标志) → bpms.sync_loan_foreclosure → BPS
A12: 全部下游表：port.basic_data_daily_loan_common、port.basic_data_loan_foreclosure、bpms.sync_loan_foreclosure
A13: ▲ 以上为「业务含义与全链路血缘」说明块；下方为原始数据 ────
A14: 字段 | B14: 7727000088 | C14: 7727000672 | D14: 7727004200 | E14: 7727000065 | F14: 7727000010
A15: id | B15: 1747370 | C15: 1746929 | D15: 1748514 | E15: 1747391 | F15: 1747384
A16: loanid | B16: 7727000088 | C16: 7727000672 | D16: 7727004200 | E16: 7727000065 | F16: 7727000010
A17: dataasof | B17: 2026-06-04 | C17: 2026-06-04 | D17: 2026-06-04 | E17: 2026-06-04 | F17: 2026-06-04
A18: shellpointloanid | B18: 1031718838 | C18: 1032761570 | D18: 0688132141 | E18: 1031718621 | F18: 1031718692
A19: propertyaddressline1 | B19: 21 LK CHARLES LN | C19: W 3120 SCHLOSSER RD | D19: 13977 W EMMA LN | E19: 2331 SW FREEMAN ST | F19: 19801 OLD BELLAMY RD
A20: propertyaddressline2 | B20: — | C20: — | D20: — | E20: — | F20: —
A21: propertycity | B21: PALM COAST | C21: MORAN | D21: METTAWA | E21: PORT SAINT LUCIE | F21: ALACHUA
A22: propertystate | B22: FL | C22: MI | D22: IL | E22: FL | F22: FL
A23: propertyzip | B23: 32137 | C23: 49760 | D23: 60045 | E23: 34953 | F23: 32615
A24: propertycounty | B24: FLAGLER | C24: MACKINAC | D24: LAKE | E24: ST. LUCIE | F24: ALACHUA
A25: propertytype | B25: 20 | C25: 20 | D25: 39 | E25: 20 | F25: 20
... A46: countycode | B46: 35 | C46: 97 | D46: 97 | E46: 111 | F46: 1

Sheet ⑦ mid·basic_data_loan_fcl
A1: port.basic_data_loan_fcl — Redshift FCL 快照中间表（portnewrezfc 全量进此；每贷款取最新 dataasof）
A2: 全 61 字段 · 取数口径：dataasof=MAX(每贷款) · 命中 5/5 贷款（无行的贷款列显示 —） · prod 实测 2026-06-04 · 业务日 2026-06-01
A3: 查询 SQL（prod 只读）： -- port.basic_data_loan_fcl · redshift_prod(只读) · 每贷款 dataasof=MAX(最新快照) · 业务日 2026-06-01 SELECT t.* FROM port.basic_data_loan_fcl t JOIN (SELECT loanid, MAX(dataasof) AS _md FROM port.basic_data_loan_fcl WHERE loanid IN ('7727000088','7727000672','7727004200','7727000065','7727000010') GROUP BY loanid) m ON t.loanid=m.loanid AND t.dataasof=m._md;
A4: 📋 业务含义与全链路血缘 〔自动生成·勿手改本块；改 outputs/fcl_table_meta.json 后重跑〕
A5: 业务含义/目的：Redshift FCL 事实表——portnewrezfc 等经改名后 UNION 全 6 家 servicer 的统一列宽表(每贷款最新 dataasof)。 FCL 计算的统一入口；屏蔽各 servicer 列名差异。
A6: 何时来查：查‘统一列名后的 FCL 字段值’，或定位某下游字段来自哪根统一列。
A7: 为什么这样处理：各家列名不同，先改名(tempfc.temp_basic_data_fcl)再 UNION 成一张统一事实表，下游只面对一套列名。
A8: 数据粒度：1 行/贷款（每贷款最新 dataasof）。
A9: 上游链路：Servicer 文件(L0) → newrez.portnewrezfc(+各家对应表) → tempfc.temp_basic_data_fcl(改名) → port.basic_data_loan_fcl〔UNION，basic_data_pool_config.py〕
A10: 全部上游表：Servicer 文件(L0)、newrez.portnewrezfc、(sls/carrington/mrc/fci/selene 对应源表)、tempfc.temp_basic_data_fcl
A11: 下游链路：basic_data_loan_fcl → { port.basic_data_loan_foreclosure〔GEN_FCL_DETAIL :253-305〕 / port.fcl_stage_info〔GEN_FCL_STAGE :1774-2440〕 / port.basic_data_loan_foreclosure_hold〔:466-768〕 / port.basic_data_loan_foreclosure_loss_mitigation〔:799-843〕 / port.basic_data_loan_foreclosure_bankruptcy〔:331-370〕 } → bpms.sync_* → 视图 → BPS
A12: 全部下游表：port.basic_data_loan_foreclosure、port.fcl_stage_info、port.basic_data_loan_foreclosure_hold、port.basic_data_loan_foreclosure_loss_mitigation、port.basic_data_loan_foreclosure_bankruptcy、bpms.sync_loan_foreclosure、bpms.sync_fcl_stage_info、bpms.sync_loan_foreclosure_hold、bpms.sync_loan_foreclosure_loss_mitigation、bpms.sync_loan_foreclosure_bankruptcy、bpms.biz_data_view_loan_details_foreclosure
A13: ▲ 以上为「业务含义与全链路血缘」说明块；下方为原始数据 ────
A14: 字段 | B14: 7727000088 | C14: 7727000672 | D14: 7727004200 | E14: 7727000065 | F14: 7727000010
A15: dataasof | B15: 2026-06-04 | C15: 2026-06-04 | D15: 2026-06-04 | E15: 2026-06-04 | F15: 2026-06-04
A16: loanid | B16: 7727000088 | C16: 7727000672 | D16: 7727004200 | E16: 7727000065 | F16: 7727000010
A17: servicer | B17: Newrez | C17: Newrez | D17: Newrez | E17: Newrez | F17: Newrez
A18: svc_loanid | B18: 1031718838 | C18: 1032761570 | D18: 0688132141 | E18: 1031718621 | F18: 1031718692
A19: activefcflag | B19: 0 | C19: 0 | D19: 0 | E19: 0 | F19: 0
A20: titleordereddate | B20: — | C20: — | D20: — | E20: 2025-11-13 | F20: —
A21: titlereceiveddate | B21: — | C21: — | D21: — | E21: 2025-12-02 | F21: —
A22: titlecleardate | B22: — | C22: — | D22: — | E22: — | F22: —
A23: noi_date | B23: — | C23: — | D23: — | E23: — | F23: —
A24: fcsetupdate | B24: 2025-05-23 | C24: 2026-03-09 | D24: 2025-06-27 | E24: 2025-02-03 | F24: —
A25: referral_start_date | B25: 2025-05-23 | C25: 2026-03-09 | D25: 2025-06-27 | E25: 2025-02-03 | F25: —
... A75: holdmodified4 | B75: — | C75: — | D75: — | E75: — | F75: —

Sheet ⑧ mid·basic_data_loan_foreclosu
A1: port.basic_data_loan_foreclosure — Redshift FCL 聚合表（1 行/贷款，sync_loan_foreclosure 的直接上游）
A2: 全 62 字段 · 取数口径：dataasof=MAX(每贷款) · 命中 5/5 贷款（无行的贷款列显示 —） · prod 实测 2026-06-04 · 业务日 2026-06-01
A3: 查询 SQL（prod 只读）： -- port.basic_data_loan_foreclosure · redshift_prod(只读) · 每贷款 dataasof=MAX(最新快照) · 业务日 2026-06-01 SELECT t.* FROM port.basic_data_loan_foreclosure t JOIN (SELECT loanid, MAX(dataasof) AS _md FROM port.basic_data_loan_foreclosure WHERE loanid IN ('7727000088','7727000672','7727004200','7727000065','7727000010') GROUP BY loanid) m ON t.loanid=m.loanid AND t.dataasof=m._md;
A4: 📋 业务含义与全链路血缘 〔自动生成·勿手改本块；改 outputs/fcl_table_meta.json 后重跑〕
A5: 业务含义/目的：Redshift FCL 聚合表(1 行/贷款)——一笔贷款端到端法拍时间线：各里程碑日期、当前状态(summary_foreclosure_status)、司法标志、在法拍天数(summary_days_in_fcl)。 bpms.sync_loan_foreclosure(BPS 主表)的直接上游；法拍主视图的数据底座。
A6: 何时来查：查某贷款法拍‘何时进入各里程碑/当前状态/在法拍多少天/为何退出’。
A7: 为什么这样处理：把事实表里散落的里程碑/状态按业务规则(GEN_FCL_DETAIL CASE)收敛成 1 行/贷款的可读时间线；退出原因直接取 servicer 的 fcremovaldesc(无解码表)。
A8: 数据粒度：1 行/贷款（含在途 + 已结）。
A9: 上游链路：… → port.basic_data_loan_fcl → port.basic_data_loan_foreclosure〔GEN_FCL_DETAIL basic_data_pool_config.py:253-305；状态 CASE :273；司法 :277-279；在法拍天数 :1628〕
A10: 全部上游表：port.basic_data_loan_fcl、tempfc.temp_basic_data_fcl、newrez.portnewrezfc、Servicer 文件(L0)
A11: 下游链路：basic_data_loan_foreclosure → (Redshift→MySQL 同步 df_db_util.py:665-699 sync_to_mysql / 702-726 update_to_mysql) → bpms.sync_loan_foreclosure〔GEN_FORECLOSURE asset_managment_config.py:535-608；实时天数校正 :597-598〕 → bpms.biz_data_view_loan_details_foreclosure(视图) → BPS Summary/Timeline 面板
A12: 全部下游表：bpms.sync_loan_foreclosure、bpms.biz_data_view_loan_details_foreclosure
A13: ▲ 以上为「业务含义与全链路血缘」说明块；下方为原始数据 ────
A14: 字段 | B14: 7727000088 | C14: 7727000672 | D14: 7727004200 | E14: 7727000065 | F14: 7727000010
A15: dataasof | B15: 2026-06-04 | C15: 2026-06-04 | D15: 2026-06-04 | E15: 2026-06-04 | F15: 2026-06-04
A16: loanid | B16: 7727000088 | C16: 7727000672 | D16: 7727004200 | E16: 7727000065 | F16: 7727000010
A17: svcloanid | B17: 1031718838 | C17: 1032761570 | D17: 0688132141 | E17: 1031718621 | F17: 1031718692
A18: servicer | B18: Newrez | C18: Newrez | D18: Newrez | E18: Newrez | F18: Newrez
A19: timeline_notice_of_intent_date | B19: — | C19: — | D19: — | E19: — | F19: —
A20: timeline_notice_of_intent_end_date | B20: — | C20: — | D20: — | E20: — | F20: —
A21: timeline_approved_for_referral_date | B21: — | C21: — | D21: — | E21: — | F21: —
A22: timeline_referred_to_attorney_date | B22: — | C22: — | D22: — | E22: — | F22: —
A23: timeline_referred_to_foreclosure_date | B23: 2025-05-23 | C23: 2026-03-09 | D23: 2025-06-27 | E23: 2025-02-03 | F23: —
A24: timeline_title_report_received_date | B24: — | C24: — | D24: — | E24: 2025-12-02 | F24: —
A25: timeline_preliminary_title_cleared_date | B25: — | C25: — | D25: — | E25: — | F25: —
... A76: summary_last_step_completed_date | B76: 2026-05-26 | C76: 2026-03-25 | D76: 2026-05-19 | E76: 2025-10-15 | F76: —

Sheet ⑨ mid·basic_data_fcl_related
A1: port.basic_data_fcl_related — FCL 关联/过滤中间表（delq_status 等；每贷款最新 dataasof）
A2: 全 14 字段 · 取数口径：dataasof=MAX(每贷款) · 命中 5/5 贷款（无行的贷款列显示 —） · prod 实测 2026-06-04 · 业务日 2026-06-01
A3: 查询 SQL（prod 只读）： -- port.basic_data_fcl_related · redshift_prod(只读) · 每贷款 dataasof=MAX(最新快照) · 业务日 2026-06-01 SELECT t.* FROM port.basic_data_fcl_related t JOIN (SELECT loanid, MAX(dataasof) AS _md FROM port.basic_data_fcl_related WHERE loanid IN ('7727000088','7727000672','7727004200','7727000065','7727000010') GROUP BY loanid) m ON t.loanid=m.loanid AND t.dataasof=m._md;
A4: 📋 业务含义与全链路血缘 〔自动生成·勿手改本块；改 outputs/fcl_table_meta.json 后重跑〕
A5: 业务含义/目的：FCL 关联属性中间表(14 列)——诉讼标志、清算类型、BK 标志、违约原因、delq_status 等。 给 stage 计算与过滤提供‘关联属性/分组键’(delq_status → stage group)。
A6: 何时来查：查某贷款 stage 分组依据、关联诉讼/清算/违约属性。
A7: 为什么这样处理：stage 计算需把逾期支线的 delq_status 与 FCL 属性合并；单列一张关联表承接，避免主时间线表过宽。
A8: 数据粒度：1 行/贷款（最新 dataasof）。
A9: 上游链路：{ port.basic_data_loan_fcl(FCL 属性) + port.basic_data_daily_loan_common_clean.delinq(逾期码) } → port.basic_data_fcl_related〔basic_data_pool_config.py〕
A10: 全部上游表：port.basic_data_loan_fcl、port.basic_data_daily_loan_common_clean
A11: 下游链路：basic_data_fcl_related.delq_status → port.fcl_stage_info.group(stage 分组) → bpms.sync_fcl_stage_info → 视图 → BPS Stage 面板
A12: 全部下游表：port.fcl_stage_info、bpms.sync_fcl_stage_info、bpms.biz_data_view_loan_details_foreclosure
A13: ▲ 以上为「业务含义与全链路血缘」说明块；下方为原始数据 ────
A14: 字段 | B14: 7727000088 | C14: 7727000672 | D14: 7727004200 | E14: 7727000065 | F14: 7727000010
A15: dataasof | B15: 2026-06-04 | C15: 2026-06-04 | D15: 2026-06-04 | E15: 2026-06-04 | F15: 2026-06-04
A16: loanid | B16: 7727000088 | C16: 7727000672 | D16: 7727004200 | E16: 7727000065 | F16: 7727000010
A17: servicer | B17: Newrez | C17: Newrez | D17: Newrez | E17: Newrez | F17: Newrez
A18: delq_status | B18: REO | C18: D120P | D18: P | E18: REO | F18: D60
A19: isloanlitigated | B19: 0 | C19: 0 | D19: 0 | E19: 0 | F19: 0
A20: deactreason | B20: FC-BK | C20: FC-BK | D20: — | E20: FC-BK | F20: —
A21: reasonfordefault | B21: Reduction in Borrower's Income | C21: — | D21: — | E21: Unable to Contact Borrower | F21: —
A22: inauctionflag | B22: 0 | C22: 0 | D22: 0 | E22: 1 | F22: 0
A23: liquidationdate | B23: — | C23: — | D23: 2026-04-16 | E23: — | F23: —
A24: liquidationtype | B24: — | C24: — | D24: 3.0 | E24: — | F24: —
A25: liquidationproceeds | B25: — | C25: — | D25: 503557.98 | E25: — | F25: —
... A28: propertystate | B28: FL | C28: MI | D28: IL | E28: FL | F28: FL

Sheet ⑩ mid·fcl_stage_info(RS)
A1: port.fcl_stage_info — Redshift 阶段表（sync_fcl_stage_info 上游；每贷款最新 fctrdt）
A2: 全 48 字段 · 取数口径：fctrdt=MAX(每贷款) · 命中 5/5 贷款（无行的贷款列显示 —） · prod 实测 2026-06-04 · 业务日 2026-06-01
A3: 查询 SQL（prod 只读）： -- port.fcl_stage_info · redshift_prod(只读) · 每贷款 fctrdt=MAX(最新快照) · 业务日 2026-06-01 SELECT t.* FROM port.fcl_stage_info t JOIN (SELECT loanid, MAX(fctrdt) AS _md FROM port.fcl_stage_info WHERE loanid IN ('7727000088','7727000672','7727004200','7727000065','7727000010') GROUP BY loanid) m ON t.loanid=m.loanid AND t.fctrdt=m._md;
A4: 📋 业务含义与全链路血缘 〔自动生成·勿手改本块；改 outputs/fcl_table_meta.json 后重跑〕
A5: 业务含义/目的：Redshift 阶段表(48 列)——把法拍拆成 6 大阶段，每阶段 5 维(开始/天数/扣除 LM-Hold 重叠等)，每贷款最新 fctrdt。 bpms.sync_fcl_stage_info(BPS 聚合 Stage/Timeline)的上游；面板‘各阶段停留天数’的底座。
A6: 何时来查：查某贷款‘在每个阶段停留多久、扣除 LM/Hold 后净时长、当前在哪个阶段组’。
A7: 为什么这样处理：业务关心‘卡在哪一步多久’；阶段口径复杂(N:N 扣 LM/Hold 重叠)，单列一张表算清，并 JOIN portfunding 取 funding 维。
A8: 数据粒度：1 行/贷款/fctrdt。
A9: 上游链路：{ port.basic_data_loan_fcl + port.basic_data_fcl_related(delq_status 分组) + port.portfunding(JOIN) } → port.fcl_stage_info〔GEN_FCL_STAGE basic_data_pool_config.py:1774-2440〕
A10: 全部上游表：port.basic_data_loan_fcl、port.basic_data_fcl_related、port.basic_data_daily_loan_common_clean、port.portfunding
A11: 下游链路：fcl_stage_info → bpms.sync_fcl_stage_info〔GET_FCL_STAGE_DATA asset_managment_config.py:925-929，JOIN port.portfunding〕 → 视图 → BPS Stage 面板
A12: 全部下游表：bpms.sync_fcl_stage_info、bpms.biz_data_view_loan_details_foreclosure
A13: ▲ 以上为「业务含义与全链路血缘」说明块；下方为原始数据 ────
A14: 字段 | B14: 7727000088 | C14: 7727000672 | D14: 7727004200 | E14: 7727000065 | F14: 7727000010
A15: fctrdt | B15: 2026-05-25 | C15: 2026-05-26 | D15: 2026-04-15 | E15: 2025-10-14 | F15: 2026-05-31
A16: loanid | B16: 7727000088 | C16: 7727000672 | D16: 7727004200 | E16: 7727000065 | F16: 7727000010
A17: group | B17: REO | C17: FCL | D17: FCL | E17: REO | F17: D120P
A18: servicer | B18: Newrez | C18: Newrez | D18: Newrez | E18: Newrez | F18: Newrez
A19: state | B19: FL | C19: MI | D19: IL | E19: FL | F19: FL
A20: judicial | B20: Y | C20: N | D20: Y | E20: Y | F20: Y
A21: demand_start_date | B21: 2025-02-18 | C21: 2025-11-17 | D21: 2025-05-20 | E21: 2024-08-12 | F21: 2026-04-10
A22: demand_end_date | B22: 2025-03-25 | C22: 2025-12-22 | D22: 2025-06-24 | E22: 2024-09-18 | F22: 2026-05-15
A23: demand_stage_days | B23: 464 | C23: 193 | D23: 333 | E23: 431 | F23: 54
A24: demand_in_lm_days | B24: — | C24: 93 | D24: 197 | E24: — | F24: —
A25: demand_on_hold_days | B25: — | C25: 17 | D25: — | E25: — | F25: —
... A62: stage | B62: JUDGEMENT | C62: SALE | D62: SALE | E62: JUDGEMENT | F62: DEMAND

Sheet ⑪ mid·portfunding
A1: port.portfunding — 融资池表（入库 JOIN 过滤；1 行/贷款）
A2: 全 57 字段 · 取数口径：当前态(1行/贷款) · 命中 5/5 贷款（无行的贷款列显示 —） · prod 实测 2026-06-04 · 业务日 2026-06-01
A3: 查询 SQL（prod 只读）： -- port.portfunding · redshift_prod(只读) · 当前态 1 行/贷款 · 业务日 2026-06-01 SELECT * FROM port.portfunding WHERE loanid IN ('7727000088','7727000672','7727004200','7727000065','7727000010') ORDER BY loanid;
A4: 📋 业务含义与全链路血缘 〔自动生成·勿手改本块；改 outputs/fcl_table_meta.json 后重跑〕
A5: 业务含义/目的：融资池表(57 列，1 行/贷款)——funding/deal 标识(fundingid/dealid)与池属性。 作为 JOIN 维度为 FCL 输出补 funding_id/bid_id，并做入库过滤。
A6: 何时来查：查某贷款属于哪个融资池/deal，或为何被 sync 过滤进/出。
A7: 为什么这样处理：BPS 需按 funding/bid 维展示与归集；FCL 表本身不含，运行时 JOIN portfunding 补齐(dealid→bid_id, fundingid→funding_id)。
A8: 数据粒度：1 行/贷款（当前态）。
A9: 上游链路：投资/融资域(非 servicer FCL 文件) → port.portfunding
A10: 全部上游表：投资/融资域来源（非 FCL servicer 文件）
A11: 下游链路：portfunding ⋈ { port.fcl_stage_info / GEN_FORECLOSURE(asset_managment_config.py:535-608) } → bpms.sync_fcl_stage_info / bpms.sync_loan_foreclosure → 视图 → BPS
A12: 全部下游表：port.fcl_stage_info、bpms.sync_fcl_stage_info、bpms.sync_loan_foreclosure、bpms.biz_data_view_loan_details_foreclosure
A13: ▲ 以上为「业务含义与全链路血缘」说明块；下方为原始数据 ────
A14: 字段 | B14: 7727000088 | C14: 7727000672 | D14: 7727004200 | E14: 7727000065 | F14: 7727000010
A15: fundingid | B15: HMP002 | C15: IMPAC001 | D15: BOA002 | E15: HMP002 | F15: HMP002
A16: dealid | B16: HMP002 | C16: IMPAC001 | D16: BOA002 | E16: HMP002 | F16: HMP002
A17: cutoffdate | B17: 2023-01-25 | C17: 2023-07-05 | D17: 2024-06-01 | E17: 2023-01-25 | F17: 2023-01-25
A18: settledate | B18: 2023-01-31 | C18: 2023-07-18 | D18: 2024-06-26 | E18: 2023-01-31 | F18: 2023-01-31
A19: wal | B19: 8.03 | C19: 8.06 | D19: 5.66 | E19: 8.03 | F19: 8.03
A20: hurdlespread | B20: 415 | C20: 408 | D20: 332 | E20: 415 | F20: 415
A21: hurdleyield | B21: 7.57 | C21: 7.54 | D21: 7.36 | E21: 7.57 | F21: 7.57
A22: loanid | B22: 7727000088 | C22: 7727000672 | D22: 7727004200 | E22: 7727000065 | F22: 7727000010
A23: sellerloanid | B23: 9010021155 | C23: 3111022026 | D23: 3260057082 | E23: 9014327961 | F23: 9014059868
A24: interestbearingupb | B24: 324035.29 | C24: 423410.11 | D24: 449829.52 | E24: 479480.42 | F24: 277928.4
A25: deferredprin | B25: 0 | C25: 0 | D25: 14062.83 | E25: 0 | F25: 0
... A71: pool | B71: A | C71: A | D71: A | E71: A | F71: A

Sheet ⑫ mid·hold
A1: port.basic_data_loan_foreclosure_hold — Redshift Hold 历史（sync_loan_foreclosure_hold 上游）
A2: 全 17 字段 · 多行/贷款（全历史） · 共 21 行 · 各贷款行数：{'7727000065': 4, '7727000088': 9, '7727000672': 2, '7727004200': 6} · prod 实测 2026-06-04
A3: 查询 SQL（prod 只读）： -- port.basic_data_loan_foreclosure_hold · redshift_prod(只读) · 多行/贷款（全历史） · 业务日 2026-06-01 SELECT * FROM port.basic_data_loan_foreclosure_hold WHERE loanid IN ('7727000088','7727000672','7727004200','7727000065','7727000010') ORDER BY loanid, fctrdt;
A4: 📋 业务含义与全链路血缘 〔自动生成·勿手改本块；改 outputs/fcl_table_meta.json 后重跑〕
A5: 业务含义/目的：Redshift Hold 历史(长表，1 行/Hold)——把源表 4 个 Hold 槽(fchold1..4)拆成长格式；Carrington 多 Hold 先排名压进 4 槽。 bpms.sync_loan_foreclosure_hold(BPS Hold 全历史)的上游；支撑‘一笔法拍多个 Hold’。
A6: 何时来查：查某贷款全部 Hold 的起止/原因/历史。
A7: 为什么这样处理：源表把 Hold 压成 4 个宽槽，业务要全历史，需拆槽(unpivot)成 1 行/Hold；一笔 FCL 多 Hold 是常态(非数据错误)。
A8: 数据粒度：1 行/贷款/Hold 段。
A9: 上游链路：newrez.portnewrezfc(fchold1..4) → port.basic_data_loan_fcl → port.basic_data_loan_foreclosure_hold〔拆槽 basic_data_pool_config.py:466-768；Carrington 排名 :504-629〕
A10: 全部上游表：newrez.portnewrezfc、port.basic_data_loan_fcl
A11: 下游链路：→ bpms.sync_loan_foreclosure_hold〔GEN_FORECLOSURE_HOLD asset_managment_config.py:847-894〕 → 视图 → BPS Hold 面板
A12: 全部下游表：bpms.sync_loan_foreclosure_hold、bpms.biz_data_view_loan_details_foreclosure
A13: ▲ 以上为「业务含义与全链路血缘」说明块；下方为原始数据 ────
A14: dataasof | B14: servicer | C14: loanid | D14: svcloanid | E14: fctrdt | F14: description1 | G14: description1_start_date | H14: description1_end_date | I14: description2 | J14: description2_start_date | K14: description2_end_date | L14: description3 | M14: description3_start_date | N14: description3_end_date | O14: description4 | P14: description4_start_date | Q14: description4_end_date
A15: 2025-05-05 | B15: Newrez | C15: 7727000065 | D15: 1031718621 | E15: 2025-05-05 | F15: Original Note | G15: 2025-02-06 | H15: 2025-03-10 | I15: — | J15: — | K15: — | L15: — | M15: — | N15: — | O15: — | P15: — | Q15: —
A16: 2025-07-02 | B16: Newrez | C16: 7727000065 | D16: 1031718621 | E16: 2025-07-02 | F16: Bankruptcy Filed | G16: 2025-05-06 | H16: 2025-06-27 | I16: Original Note | J16: 2025-02-06 | K16: 2025-03-10 | L16: — | M16: — | N16: — | O16: — | P16: — | Q16: —
A17: 2025-08-26 | B17: Newrez | C17: 7727000065 | D17: 1031718621 | E17: 2025-08-26 | F17: Court Delay | G17: 2025-07-02 | H17: 2025-07-14 | I17: Bankruptcy Filed | J17: 2025-05-06 | K17: 2025-06-27 | L17: Original Note | M17: 2025-02-06 | N17: 2025-03-10 | O17: — | P17: — | Q17: —
A18: 2026-06-04 | B18: Newrez | C18: 7727000065 | D18: 1031718621 | E18: 2026-06-04 | F18: Court Delay | G18: 2025-08-26 | H18: 2025-08-28 | I18: Court Delay | J18: 2025-07-02 | K18: 2025-07-14 | L18: Bankruptcy Filed | M18: 2025-05-06 | N18: 2025-06-27 | O18: — | P18: — | Q18: —
A19: 2025-07-15 | B19: Newrez | C19: 7727000088 | D19: 1031718838 | E19: 2025-07-15 | F19: Original Note | G19: 2025-05-28 | H19: 2025-06-11 | I19: — | J19: — | K19: — | L19: — | M19: — | N19: — | O19: — | P19: — | Q19: —
A20: 2025-07-30 | B20: Newrez | C20: 7727000088 | D20: 1031718838 | E20: 2025-07-30 | F20: Service Delay | G20: 2025-07-15 | H20: — | I20: Original Note | J20: 2025-05-28 | K20: 2025-06-11 | L20: — | M20: — | N20: — | O20: — | P20: — | Q20: —
A21: 2025-08-12 | B21: Newrez | C21: 7727000088 | D21: 1031718838 | E21: 2025-08-12 | F21: Loss Mitigation Workout | G21: 2025-07-31 | H21: 2025-08-01 | I21: Service Delay | J21: 2025-07-15 | K21: 2025-07-31 | L21: Original Note | M21: 2025-05-28 | N21: 2025-06-11 | O21: — | P21: — | Q21: —
A22: 2025-10-21 | B22: Newrez | C22: 7727000088 | D22: 1031718838 | E22: 2025-10-21 | F22: Loss Mitigation Workout | G22: 2025-08-13 | H22: 2025-10-21 | I22: Loss Mitigation Workout | J22: 2025-07-31 | K22: 2025-08-01 | L22: Service Delay | M22: 2025-07-15 | N22: 2025-07-31 | O22: — | P22: — | Q22: —
A23: 2026-01-18 | B23: Newrez | C23: 7727000088 | D23: 1031718838 | E23: 2026-01-18 | F23: Court Delay | G23: 2025-10-21 | H23: 2025-12-16 | I23: Loss Mitigation Workout | J23: 2025-08-13 | K23: 2025-10-21 | L23: Loss Mitigation Workout | M23: 2025-07-31 | N23: 2025-08-01 | O23: — | P23: — | Q23: —
A24: 2026-02-23 | B24: Newrez | C24: 7727000088 | D24: 1031718838 | E24: 2026-02-23 | F24: Loss Mitigation Workout | G24: 2026-02-20 | H24: — | I24: Court Delay | J24: 2026-01-16 | K24: — | L24: Court Delay | M24: 2025-10-21 | N24: 2025-12-16 | O24: — | P24: — | Q24: —
A25: 2026-03-16 | B25: Newrez | C25: 7727000088 | D25: 1031718838 | E25: 2026-03-16 | F25: Court Delay | G25: 2026-01-16 | H25: — | I25: Loss Mitigation Workout | J25: 2026-02-20 | K25: 2026-02-24 | L25: Court Delay | M25: 2025-10-21 | N25: 2025-12-16 | O25: — | P25: — | Q25: —
... A35: 2026-06-04 | B35: Newrez | C35: 7727004200 | D35: 0688132141 | E35: 2026-06-04 | F35: Delinquency Review | G35: 2026-04-17 | H35: 2026-04-17 | I35: Hearing Set | J35: 2026-01-29 | K35: 2026-02-13 | L35: Service Delay | M35: 2025-12-30 | N35: 2026-01-23 | O35: — | P35: — | Q35: —

Sheet ⑬ mid·loss_mitigation
A1: port.basic_data_loan_foreclosure_loss_mitigation — Redshift LM 历史（上游）
A2: 全 16 字段 · 多行/贷款（全历史） · 共 21 行 · 各贷款行数：{'7727000010': 2, '7727000065': 2, '7727000088': 9, '7727000672': 2, '7727004200': 6} · prod 实测 2026-06-04
A3: 查询 SQL（prod 只读）： -- port.basic_data_loan_foreclosure_loss_mitigation · redshift_prod(只读) · 多行/贷款（全历史） · 业务日 2026-06-01 SELECT * FROM port.basic_data_loan_foreclosure_loss_mitigation WHERE loanid IN ('7727000088','7727000672','7727004200','7727000065','7727000010') ORDER BY loanid, fctrdt;
A4: 📋 业务含义与全链路血缘 〔自动生成·勿手改本块；改 outputs/fcl_table_meta.json 后重跑〕
A5: 业务含义/目的：Redshift LM 历史(1 行/LM 周期)——按 (loanid, dealstartdate)，datadic 解码 lmdeal/lmprogram/lmstatus/lmdecision。 bpms.sync_loan_foreclosure_loss_mitigation 的上游；支撑‘一笔贷款多 LM 周期’。
A6: 何时来查：查某贷款全部 LM 周期/项目/决定(已解码)。
A7: 为什么这样处理：LM 多周期是常态；编码需经 datadic 解码成业务文案(JOIN key 拼 code+'.0')。
A8: 数据粒度：1 行/贷款/LM 周期。
A9: 上游链路：{ newrez.portnewrezlm + newrez.portnewrezdatadic } → port.basic_data_loan_fcl 体系 → port.basic_data_loan_foreclosure_loss_mitigation〔basic_data_pool_config.py:799-843〕
A10: 全部上游表：newrez.portnewrezlm、newrez.portnewrezdatadic、port.basic_data_loan_fcl
A11: 下游链路：→ bpms.sync_loan_foreclosure_loss_mitigation〔asset_managment_config.py:799-819〕 → 视图 → BPS LM 面板
A12: 全部下游表：bpms.sync_loan_foreclosure_loss_mitigation、bpms.biz_data_view_loan_details_foreclosure
A13: ▲ 以上为「业务含义与全链路血缘」说明块；下方为原始数据 ────
A14: dataasof | B14: servicer | C14: loanid | D14: svcloanid | E14: fctrdt | F14: deal | G14: program | H14: lmc_status | I14: cycle_opened_date | J14: cycle_closed_date | K14: final_disposition | L14: improgram | M14: denialreason | N14: borrower_intentions | O14: imminent_default | P14: single_point_of_contact
A15: 2026-04-15 | B15: Newrez | C15: 7727000010 | D15: 1031718692 | E15: 2026-04-15 | F15: Evaluation | G15: Evaluation | H15: Pending Financials | I15: 2024-11-26 | J15: 2024-12-23 | K15: Request Incomplete/Failed to Provide Information | L15: 21.0 | M15: — | N15: — | O15: — | P15: —
A16: 2026-06-04 | B16: Newrez | C16: 7727000010 | D16: 1031718692 | E16: 2026-06-04 | F16: Modification | G16: 498.0 | H16: Workout Denial | I16: 2026-04-16 | J16: 2026-04-28 | K16: Referral to FC | L16: 498.0 | M16: Hardship not resolved | N16: — | O16: — | P16: —
A17: 2025-06-30 | B17: Newrez | C17: 7727000065 | D17: 1031718621 | E17: 2025-06-30 | F17: Evaluation | G17: Evaluation | H17: Pending Financials | I17: 2024-11-26 | J17: 2024-12-23 | K17: Request Incomplete/Failed to Provide Information | L17: 21.0 | M17: — | N17: — | O17: — | P17: —
A18: 2026-06-04 | B18: Newrez | C18: 7727000065 | D18: 1031718621 | E18: 2026-06-04 | F18: Evaluation | G18: Evaluation | H18: Pending Financials | I18: 2025-07-01 | J18: 2025-07-01 | K18: LMS Opened in Error | L18: 21.0 | M18: — | N18: — | O18: — | P18: —
A19: 2025-01-29 | B19: Newrez | C19: 7727000088 | D19: 1031718838 | E19: 2025-01-29 | F19: Evaluation | G19: Evaluation | H19: Pending Financials | I19: 2024-09-20 | J19: 2024-10-21 | K19: Request Incomplete/Failed to Provide Information | L19: 21.0 | M19: — | N19: — | O19: — | P19: —
A20: 2025-03-16 | B20: Newrez | C20: 7727000088 | D20: 1031718838 | E20: 2025-03-16 | F20: Modification | G20: Bridger mod | H20: Workout Denial | I20: 2025-01-30 | J20: 2025-03-11 | K20: Referral to FC | L20: 419.0 | M20: — | N20: — | O20: — | P20: —
A21: 2025-05-07 | B21: Newrez | C21: 7727000088 | D21: 1031718838 | E21: 2025-05-07 | F21: Modification | G21: Bridger mod | H21: Workout Denial | I21: 2025-03-17 | J21: 2025-04-29 | K21: Referral to FC | L21: 419.0 | M21: Request Incomplete/Failed to Provide Documentation | N21: — | O21: — | P21: —
A22: 2025-06-19 | B22: Newrez | C22: 7727000088 | D22: 1031718838 | E22: 2025-06-19 | F22: Modification | G22: Bridger mod | H22: Workout Denial | I22: 2025-05-08 | J22: 2025-06-14 | K22: Referral to FC | L22: 419.0 | M22: Request Incomplete/Failed to Provide Documentation | N22: — | O22: — | P22: —
A23: 2025-10-20 | B23: Newrez | C23: 7727000088 | D23: 1031718838 | E23: 2025-10-20 | F23: Modification | G23: 496.0 | H23: Workout Denial | I23: 2025-06-20 | J23: 2025-10-20 | K23: Referral to FC | L23: 496.0 | M23: — | N23: — | O23: — | P23: —
A24: 2025-12-09 | B24: Newrez | C24: 7727000088 | D24: 1031718838 | E24: 2025-12-09 | F24: Short Sale | G24: Short Sale | H24: Document Follow-up | I24: 2025-10-20 | J24: 2025-11-21 | K24: Request Incomplete/Failed to Provide Information | L24: 8.0 | M24: — | N24: — | O24: — | P24: —
A25: 2026-01-27 | B25: Newrez | C25: 7727000088 | D25: 1031718838 | E25: 2026-01-27 | F25: DIL | G25: Deed-in-Lieu | H25: DIL Title Ordered | I25: 2025-12-10 | J25: 2026-01-27 | K25: LMS Opened in Error | L25: 10.0 | M25: — | N25: — | O25: — | P25: —
... A35: 2026-06-04 | B35: Newrez | C35: 7727004200 | D35: 0688132141 | E35: 2026-06-04 | F35: Modification | G35: 496.0 | H35: Document Follow-up | I35: 2026-01-06 | J35: 2026-02-02 | K35: Request Incomplete/Failed to Provide Information | L35: 496.0 | M35: — | N35: — | O35: — | P35: —

Sheet ⑭ mid·bankruptcy
A1: port.basic_data_loan_foreclosure_bankruptcy — Redshift 破产历史（上游）
A2: 全 15 字段 · 多行/贷款（全历史） · 共 3 行 · 各贷款行数：{'7727000010': 2, '7727000065': 1} · prod 实测 2026-06-04
A3: 查询 SQL（prod 只读）： -- port.basic_data_loan_foreclosure_bankruptcy · redshift_prod(只读) · 多行/贷款（全历史） · 业务日 2026-06-01 SELECT * FROM port.basic_data_loan_foreclosure_bankruptcy WHERE loanid IN ('7727000088','7727000672','7727004200','7727000065','7727000010') ORDER BY loanid, fctrdt;
